 * Serving Flask app 'app' (lazy loading)
 * Environment: production
   WARNING: This is a development server. Do not use it in a production deployment.
   Use a production WSGI server instead.
 * Debug mode: off
 * Running on http://127.0.0.1:5000/ (Press CTRL+C to quit)
888-888-8888 Earth
[2023-01-02 14:43:12,220] ERROR in app: Exception on /api/addprofile [POST]
Traceback (most recent call last):
  File "C:\Users\Dominic\Desktop\Coding temple\FINAL\venv\lib\site-packages\sqlalchemy\engine\base.py", line 1770, in _execute_context
    self.dialect.do_execute(
  File "C:\Users\Dominic\Desktop\Coding temple\FINAL\venv\lib\site-packages\sqlalchemy\engine\default.py", line 717, in do_execute    
    cursor.execute(statement, parameters)
psycopg2.ProgrammingError: can't adapt type 'function'

The above exception was the direct cause of the following exception:

Traceback (most recent call last):
  File "C:\Users\Dominic\Desktop\Coding temple\FINAL\app\api\routes.py", line 31, in add_profile
    db.session.commit()
  File "<string>", line 2, in commit
  File "C:\Users\Dominic\Desktop\Coding temple\FINAL\venv\lib\site-packages\sqlalchemy\orm\session.py", line 1428, in commit
    self._transaction.commit(_to_root=self.future)
  File "C:\Users\Dominic\Desktop\Coding temple\FINAL\venv\lib\site-packages\sqlalchemy\orm\session.py", line 829, in commit
    self._prepare_impl()
  File "C:\Users\Dominic\Desktop\Coding temple\FINAL\venv\lib\site-packages\sqlalchemy\orm\session.py", line 808, in _prepare_impl
    self.session.flush()
  File "C:\Users\Dominic\Desktop\Coding temple\FINAL\venv\lib\site-packages\sqlalchemy\orm\session.py", line 3298, in flush
    self._flush(objects)
  File "C:\Users\Dominic\Desktop\Coding temple\FINAL\venv\lib\site-packages\sqlalchemy\orm\session.py", line 3437, in _flush
    with util.safe_reraise():
  File "C:\Users\Dominic\Desktop\Coding temple\FINAL\venv\lib\site-packages\sqlalchemy\util\langhelpers.py", line 70, in __exit__
    compat.raise_(
  File "C:\Users\Dominic\Desktop\Coding temple\FINAL\venv\lib\site-packages\sqlalchemy\util\compat.py", line 207, in raise_
    raise exception
  File "C:\Users\Dominic\Desktop\Coding temple\FINAL\venv\lib\site-packages\sqlalchemy\orm\session.py", line 3398, in _flush
    flush_context.execute()
  File "C:\Users\Dominic\Desktop\Coding temple\FINAL\venv\lib\site-packages\sqlalchemy\orm\unitofwork.py", line 456, in execute
    rec.execute(self)
  File "C:\Users\Dominic\Desktop\Coding temple\FINAL\venv\lib\site-packages\sqlalchemy\orm\unitofwork.py", line 630, in execute
    util.preloaded.orm_persistence.save_obj(
  File "C:\Users\Dominic\Desktop\Coding temple\FINAL\venv\lib\site-packages\sqlalchemy\orm\persistence.py", line 242, in save_obj
    _emit_insert_statements(
  File "C:\Users\Dominic\Desktop\Coding temple\FINAL\venv\lib\site-packages\sqlalchemy\orm\persistence.py", line 1094, in _emit_insert_statements
    c = connection._execute_20(
  File "C:\Users\Dominic\Desktop\Coding temple\FINAL\venv\lib\site-packages\sqlalchemy\engine\base.py", line 1582, in _execute_20
    return meth(self, args_10style, kwargs_10style, execution_options)
  File "C:\Users\Dominic\Desktop\Coding temple\FINAL\venv\lib\site-packages\sqlalchemy\sql\elements.py", line 324, in _execute_on_connection
    return connection._execute_clauseelement(
  File "C:\Users\Dominic\Desktop\Coding temple\FINAL\venv\lib\site-packages\sqlalchemy\engine\base.py", line 1451, in _execute_clauseelement
    ret = self._execute_context(
  File "C:\Users\Dominic\Desktop\Coding temple\FINAL\venv\lib\site-packages\sqlalchemy\engine\base.py", line 1813, in _execute_context
    self._handle_dbapi_exception(
  File "C:\Users\Dominic\Desktop\Coding temple\FINAL\venv\lib\site-packages\sqlalchemy\engine\base.py", line 1994, in _handle_dbapi_exception
    util.raise_(
  File "C:\Users\Dominic\Desktop\Coding temple\FINAL\venv\lib\site-packages\sqlalchemy\util\compat.py", line 207, in raise_
    raise exception
  File "C:\Users\Dominic\Desktop\Coding temple\FINAL\venv\lib\site-packages\sqlalchemy\engine\base.py", line 1770, in _execute_context
    self.dialect.do_execute(
  File "C:\Users\Dominic\Desktop\Coding temple\FINAL\venv\lib\site-packages\sqlalchemy\engine\default.py", line 717, in do_execute
    cursor.execute(statement, parameters)
sqlalchemy.exc.ProgrammingError: (psycopg2.ProgrammingError) can't adapt type 'function'
[SQL: INSERT INTO profile (id, display_name, profession, phone_number, location, hobbies, user_token) VALUES (%(id)s, %(display_name)s, %(profession)s, %(phone_number)s, %(location)s, %(hobbies)s, %(user_token)s)]
[parameters: {'id': 'jFJRFlI98gEEnu49gQpYgqDiugM4tURH16LkX2lxzB8', 'display_name': 'Dommy', 'profession': 'Maintenance Technician', 'phone_number': '888-888-8888', 'location': 'Earth', 'hobbies': 'Coding', 'user_token': <function get_token at 0x00000206D4C7DB40>}]
(Background on this error at: http://sqlalche.me/e/14/f405)

During handling of the above exception, another exception occurred:

Traceback (most recent call last):
  File "C:\Users\Dominic\Desktop\Coding temple\FINAL\venv\lib\site-packages\flask\app.py", line 2070, in wsgi_app
    response = self.full_dispatch_request()
  File "C:\Users\Dominic\Desktop\Coding temple\FINAL\venv\lib\site-packages\flask\app.py", line 1515, in full_dispatch_request
    rv = self.handle_user_exception(e)
  File "C:\Users\Dominic\Desktop\Coding temple\FINAL\venv\lib\site-packages\flask_cors\extension.py", line 165, in wrapped_function
    return cors_after_request(app.make_response(f(*args, **kwargs)))
  File "C:\Users\Dominic\Desktop\Coding temple\FINAL\venv\lib\site-packages\flask\app.py", line 1513, in full_dispatch_request
    rv = self.dispatch_request()
  File "C:\Users\Dominic\Desktop\Coding temple\FINAL\venv\lib\site-packages\flask\app.py", line 1499, in dispatch_request
    return self.ensure_sync(self.view_functions[rule.endpoint])(**req.view_args)
  File "C:\Users\Dominic\Desktop\Coding temple\FINAL\app\api\routes.py", line 37, in add_profile
    raise Exception('Invalid form data: Please check your form')
Exception: Invalid form data: Please check your form
127.0.0.1 - - [02/Jan/2023 14:43:12] "POST /api/addprofile HTTP/1.1" 500 -